Traceback (most recent call last):
  File "cacher.py", line 7, in <module>
    from BeautifulSoup import BeautifulSoup;
ImportError: No module named 'BeautifulSoup'

During handling of the above exception, another exception occurred:

Traceback (most recent call last):
  File "cacher.py", line 9, in <module>
    from bs4 import BeautifulSoup;
ImportError: No module named 'bs4'
